<?xml version="1.0"?>
<robot xmlns:xacro="http://ros.org/wiki/xacro">

	<!--
		HUMAN HAND MODEL v 0.1 
    urdf derived from pisa soft_hand
    author Guillaume Walck
    meshes from GrabCAD, author Joerg Schmit
		original CAD model available at: https://grabcad.com/library/human-left-hand/
	-->

	<xacro:include filename="$(find pisa_hand_description)/model/materials.urdf.xacro"/>

	<xacro:property name="pi" value="3.1415926535897931" />

	<!-- joint properties -->
	<xacro:property name="abd_lb" value="-30" />
	<xacro:property name="abd_ub" value="30" />
	<xacro:property name="thumb_abd_lb" value="0" />
	<xacro:property name="thumb_abd_ub" value="90" />
	<xacro:property name="inner_lb" value="0" />
	<xacro:property name="inner_ub" value="90" />
	<xacro:property name="middle_lb" value="0" />
	<xacro:property name="middle_ub" value="90" />
	<xacro:property name="outer_lb" value="0" />
	<xacro:property name="outer_ub" value="90" />
	<xacro:property name="velocity" value="100" />
	<xacro:property name="effort" value="100" />
	<xacro:property name="damping" value="0.0" />
	<xacro:property name="friction" value="0.0" />

  <!-- link properties -->
  <xacro:property name="thumb_base_len" value="0.05415" />
  <xacro:property name="thumb_proximal_len" value="0.03803" />
  <xacro:property name="index_middle_len" value="0.027" />
  <xacro:property name="index_proximal_len" value="0.046" />
  <xacro:property name="middle_middle_len" value="0.033" />
  <xacro:property name="middle_proximal_len" value="0.0495" />
  <xacro:property name="ring_middle_len" value="0.033" />
  <xacro:property name="ring_proximal_len" value="0.048" />
  <xacro:property name="little_middle_len" value="0.0215" />
  <xacro:property name="little_proximal_len" value="0.037" />
  
	<!-- synergy vector -->
	<xacro:property name="thumb_abd_R" value="1.3" />
	<xacro:property name="thumb_inner_R" value="1.3" />
	<xacro:property name="thumb_outer_R" value="1.0" />
	<xacro:property name="index_abd_R" value="-0.2" />
	<xacro:property name="index_inner_R" value="1.0" />
	<xacro:property name="index_middle_R" value="1.0" />
	<xacro:property name="index_outer_R" value="1.0" />
	<xacro:property name="middle_abd_R" value="0.0" />
	<xacro:property name="middle_inner_R" value="1.0" />
	<xacro:property name="middle_middle_R" value="1.0" />
	<xacro:property name="middle_outer_R" value="1.0" />
	<xacro:property name="ring_abd_R" value="0.2" />
	<xacro:property name="ring_inner_R" value="1.0" />
	<xacro:property name="ring_middle_R" value="1.0" />
	<xacro:property name="ring_outer_R" value="1.0" />
	<xacro:property name="little_abd_R" value="0.4" />
	<xacro:property name="little_inner_R" value="1.0" />
	<xacro:property name="little_middle_R" value="1.0" />
	<xacro:property name="little_outer_R" value="1.0" />

	<!-- synergy joint properties -->
	<xacro:property name="synergy_lb" value="0.0" />
	<xacro:property name="synergy_ub" value="1.0" />
	<xacro:property name="max_synergy_velocity" value="100" />
	<xacro:property name="max_synergy_effort" value="100" />
	<xacro:property name="synergy_damping" value="0.0" />
	<xacro:property name="synergy_friction" value="0.0" />

	<!-- SOFT FINGER model -->
	<!-- 4 fingers are equal (index, middle, ring, little) -->
	<xacro:macro name="soft_finger" params="parent parent_name prefix name position orientation proximal_len middle_len abd_R index:=1 middle:=0 ring:=0 little:=0 ">

		<!-- KNUCKLE -->
		<joint name="${prefix}${name}_abd_joint" type="revolute">
			<origin xyz="${position}" rpy="${orientation}" />
			<parent link="${parent}"/>
			<child link="${prefix}${name}_knuckle_link"/>
			<axis xyz="0 -1 0" />
			<limit lower="${abd_lb *pi/180}" upper="${abd_ub *pi/180}" effort="${effort}" velocity="${velocity}"/>
			<dynamics damping="${damping}" friction="${friction}"/>
		</joint>
		
		<link name="${prefix}${name}_knuckle_link">
		</link>

		<!-- PROXIMAL PHALANGE -->
		<joint name="${prefix}${name}_inner_joint" type="revolute">
			<origin xyz="0 0 0" rpy="0 0 0" />
			<parent link="${prefix}${name}_knuckle_link"/>
			<child link="${prefix}${name}_proximal_link"/>
			<axis xyz="1 0 0" />
			<limit lower="${inner_lb *pi/180}" upper="${inner_ub *pi/180}" effort="${effort}" velocity="${velocity}"/>
			<dynamics damping="${damping}" friction="${friction}"/>
		</joint>


		<link name="${prefix}${name}_proximal_link">
			<!-- <inertial>
				<insert_block name="phalanx_inertia"/>
			</inertial> -->
			<visual>
				<geometry>
            <mesh filename="package://pisa_hand_description/meshes/${name}_proximal.stl" scale="0.001 0.001 .001" />
				</geometry>
				<material name="HumanHand/Skin" />
			</visual>
		</link>

		<!-- MIDDLE PHALANGE -->
		<joint name="${prefix}${name}_middle_joint" type="revolute">
			<origin xyz="0 0 ${proximal_len}" rpy="0 0 0" />
			<parent link="${prefix}${name}_proximal_link"/>
			<child link="${prefix}${name}_middle_link"/>
			<axis xyz="1 0 0" />
			<limit lower="${middle_lb *pi/180}" upper="${middle_ub *pi/180}" effort="${effort}" velocity="${velocity}"/>
			<dynamics damping="${damping}" friction="${friction}"/>
		</joint>

		
		<link name="${prefix}${name}_middle_link">
			<visual>
				<geometry>
					<mesh filename="package://pisa_hand_description/meshes/${name}_middle.stl" scale="0.001 0.001 .001" />
				</geometry>
				<material name="HumanHand/Skin" />
			</visual>
		</link>

		<!-- DISTAL PHALANGE -->
		<joint name="${prefix}${name}_outer_joint" type="revolute">
			<origin xyz="0.0 0 ${middle_len}" rpy="0 0 0" />
			<parent link="${prefix}${name}_middle_link"/>
			<child link="${prefix}${name}_distal_link"/>
			<axis xyz="1 0 0" />
			<limit lower="${outer_lb *pi/180}" upper="${outer_ub *pi/180}" effort="${effort}" velocity="${velocity}"/>
			<dynamics damping="${damping}" friction="${friction}"/>
		</joint>

		<link name="${prefix}${name}_distal_link">
			<visual> 
				<geometry>
					<mesh filename="package://pisa_hand_description/meshes/${name}_distal.stl" scale=" 0.001 0.001 .001" /> 
				</geometry>
				 <material name="HumanHand/Skin" /> 
			</visual>
		</link>

	</xacro:macro>

	<!-- THUMB MODEL -->
	<!-- It has one joint less than rest of fingers -->
	<xacro:macro name="soft_thumb" params="parent parent_name name position orientation base_len proximal_len abd_R ">

		<!-- THUMB RIGHT HAND -->
			<!-- KNUCKLE -->
			<joint name="${name}_abd_joint" type="revolute">
				<origin xyz="${position}" rpy="${orientation}" />
				<parent link="${parent}"/>
				<child link="${name}_fake_link"/>
				<axis xyz="1 0 0" />
				<limit lower="${thumb_abd_lb *pi/180}" upper="${thumb_abd_ub *pi/180}" effort="${effort}" velocity="${velocity}"/>
				<dynamics damping="${damping}" friction="${friction}"/>
			</joint>

			<link name="${name}_fake_link">

			</link>

			<joint name="${name}_rot_joint" type="revolute">
				<origin xyz="0 0 0" rpy="0 0 0" /> 
				<parent link="${name}_fake_link"/>
				<child link="${name}_knuckle_link"/>
				<axis xyz="0 -1 0" />
				<limit lower="${thumb_abd_lb *pi/180}" upper="${thumb_abd_ub *pi/180}" effort="${effort}" velocity="${velocity}"/>
				<dynamics damping="${damping}" friction="${friction}"/>
			</joint>
			
			<link name="${name}_knuckle_link">
				<visual>
          <origin xyz="0 0 0" rpy="0 0 0" /> 
					<geometry>
						<mesh filename="package://pisa_hand_description/meshes/thumb_base.stl" scale=" 0.001 0.001 .001" />
					</geometry>
					<material name="HumanHand/Skin" />
				</visual>
			</link>

			<!-- PROXIMAL PHALANGE -->
			    <joint name="${name}_inner_joint" type="revolute">
	           	<origin xyz="0.0 0.0 ${base_len}" rpy="0.0 0.0 0.0" />  
	   
				<parent link="${name}_knuckle_link"/>
				<child link="${name}_proximal_link"/>
				<axis xyz="0 -1 0" />
				<limit lower="${inner_lb *pi/180}" upper="${inner_ub *pi/180}" effort="${effort}" velocity="${velocity}"/>
				<dynamics damping="${damping}" friction="${friction}"/>
			</joint>

		<link name="${name}_proximal_link">
			<visual>
				<geometry>
					<mesh filename="package://pisa_hand_description/meshes/thumb_proximal.stl" scale="0.001 0.001 .001" />
				</geometry>
				<material name="HumanHand/Skin" />
			</visual>
		</link>

		<!-- DISTAL PHALANGE -->
		<joint name="${name}_outer_joint" type="revolute">
			<origin xyz="0.0 0 ${proximal_len}" rpy="0 0 0" />
			<parent link="${name}_proximal_link"/>
			<child link="${name}_distal_link"/>
			<axis xyz="0 -1 0" />
			<limit lower="${outer_lb *pi/180}" upper="${outer_ub *pi/180}" effort="${effort}" velocity="${velocity}"/>
		</joint>

		<link name="${name}_distal_link">
			<visual>
				<geometry>
					<mesh filename="package://pisa_hand_description/meshes/thumb_distal.stl" scale=" 0.001 0.001 .001" />
				</geometry>
				<material name="HumanHand/Skin" />
			</visual>
		</link>
	</xacro:macro>

	<!-- HUMAN HAND MODEL -->
	<xacro:macro name="human_hand" params="parent name left *origin">

		<!-- PALM -->
		<joint name="${name}_palm_joint" type="fixed" >
			<origin xyz="-0.01 0 0.06" rpy="0 0 0" />
			<insert_block name="origin"/>
			<parent link="${parent}" />
			<child link="${name}_palm_link" />
		</joint>

		<link name="${name}_palm_link">
			<xacro:if value="${left}">
				<visual>
					<geometry>
						<mesh filename="package://pisa_hand_description/meshes/palm.stl" scale="-0.001 -0.001 -0.001" />
					</geometry>
					<material name="HumanHand/Skin" />
				</visual>
			</xacro:if>
			<xacro:unless value="${left}">
				<visual>
					<geometry>
						<mesh filename="package://pisa_hand_description/meshes/palm.stl" scale=" .001 .001 .001" />
					</geometry>
					<material name="HumanHand/Skin" />
				</visual>
			</xacro:unless>
		</link>

		<!-- THUMB AND FINGERS -->
			<xacro:soft_thumb parent="${name}_palm_link" parent_name="${name}" name="${name}_thumb" position="0.02475 -0.0125 0.0125" orientation="0.0 0.6240 0" base_len="${thumb_base_len}" proximal_len="${thumb_proximal_len}" abd_R="${thumb_abd_R *(thumb_abd_ub - thumb_abd_lb)*pi/180}"  />

			<xacro:soft_finger parent="${name}_palm_link" parent_name="${name}" prefix="${name}_" name="index" position="0.02175 -0.002 0.099" orientation="0 0 0" proximal_len="${index_proximal_len}" middle_len="${index_middle_len}"  abd_R="${index_abd_R}"  />

			<xacro:soft_finger parent="${name}_palm_link" parent_name="${name}" prefix="${name}_" name="middle" position="-0.002 0.0015 0.0955" orientation="0 0 0.0" proximal_len="${middle_proximal_len}" middle_len="${middle_middle_len}" abd_R="${middle_abd_R}"  />

			<xacro:soft_finger parent="${name}_palm_link" parent_name="${name}" prefix="${name}_" name="ring" position="-0.02225 0.0010 0.090" orientation="0 0 0" proximal_len="${ring_proximal_len}" middle_len="${ring_middle_len}" abd_R="${ring_abd_R}" />

			<xacro:soft_finger parent="${name}_palm_link" parent_name="${name}" prefix="${name}_" name="little" position=" -0.04175 -0.003 0.079" orientation="0 0 0" proximal_len="${little_proximal_len}" middle_len="${little_middle_len}" abd_R="${little_abd_R}" />
	
		
	</xacro:macro>

</robot>
