<?xml version="1.0"?>
<robot xmlns:xacro="http://www.ros.org/wiki/xacro" name="pisa_hand">

	<xacro:include filename="$(find pisa_hand_description)/model/pisa_hand.urdf.xacro"/>

	<link name="box">
		<!-- <inertial>
			<mass value="50.0"/>
			<inertia  ixx="1" ixy="0.00"  ixz="0.00" iyy="1" iyz="0.00" izz="1" />
		</inertial> -->
		<visual>
			<origin xyz="0 0 0.50" rpy="0 0 0"/>
			<geometry>
				<box size="1.0 1.0 1.0"/>
			</geometry>
		</visual>
		<!-- <collision>
			<origin xyz="0 0 0.50" rpy="0 0 0"/>
			<geometry>
				<box size="1.0 1.0 1.0"/>
			</geometry>
		</collision> -->
	</link>
<!--
	<joint name="box_wrist_left_joint" type="fixed">
		<origin xyz="0 -0.2 1.02" rpy="0 0 0" />
		<parent link="box"/>
		<child link="wrist_left"/>
	</joint>

	<link name="wrist_left">
		<inertial>
			<mass value="1.0"/>
			<inertia  ixx="0.01" ixy="0.00"  ixz="0.00" iyy="0.01" iyz="0.00" izz="0.01" />
		</inertial>
		<visual>
			<geometry>
				<mesh filename="package://pisa_hand_description/meshes/coman_coupler_left.stl" scale=" .001 .001 .001" />
			</geometry>
			<material name="SoftHand/LightBlue" />
		</visual>
		<collision>
			<geometry>
				<mesh filename="package://pisa_hand_description/meshes/coman_coupler_left.stl" scale=" .001 .001 .001" />
			</geometry>
		</collision>
	</link>

	<xacro:pisa_hand parent="wrist_left" name="pisa_hand_left" withAdaptiveTransmission="true" useMimicTag="$(arg use_mimic_tag)" left="true">
		<origin xyz="0.002 -0.009 0.038" rpy="0 0 0"/>
	</xacro:pisa_hand>
-->
	<joint name="box_wrist_right_joint_1" type="revolute">
		<origin xyz="0 0.2 1.02" rpy="0 0 0" />
		<parent link="box"/>
		<child link="wrist_right_fake_1"/>
				<axis xyz="1 0 0" />
				<limit lower="${abd_lb *pi/180}" upper="${abd_ub *pi/180}" effort="${effort}" velocity="${velocity}"/>
    	<dynamics damping="${damping}" friction="${friction}"/>
	</joint>
	<link name="wrist_right_fake_1">
	</link>


	<joint name="box_wrist_right_joint_2" type="revolute">
		<origin xyz="0 0 0" rpy="0 0 0" />
		<parent link="wrist_right_fake_1"/>
		<child link="wrist_right_fake_2"/>
				<axis xyz="0 1 0" />
				<limit lower="${abd_lb *pi/180}" upper="${abd_ub *pi/180}" effort="${effort}" velocity="${velocity}"/>
    	<dynamics damping="${damping}" friction="${friction}"/>
	</joint>
	<link name="wrist_right_fake_2">
	</link>

	<joint name="box_wrist_right_joint_3" type="revolute">
		<origin xyz="0 0 0" rpy="0 0 0" />
		<parent link="wrist_right_fake_2"/>
		<child link="wrist_right"/>
				<axis xyz="0 0 1" />
				<limit lower="${abd_lb *pi/180}" upper="${abd_ub *pi/180}" effort="${effort}" velocity="${velocity}"/>
    	<dynamics damping="${damping}" friction="${friction}"/>
	</joint>
	


	<link name="wrist_right">
		<!-- <inertial>
			<mass value="1.0"/>
			<inertia  ixx="0.01" ixy="0.00"  ixz="0.00" iyy="0.01" iyz="0.00" izz="0.01" />
		</inertial>
		<visual>
			<geometry>
				<mesh filename="package://pisa_hand_description/meshes/coman_coupler_right.stl" scale=" .001 .001 .001"/>
			</geometry>
			<material name="SoftHand/LightBlue" />
		</visual>
		<collision>
			<geometry>
				<mesh filename="package://pisa_hand_description/meshes/coman_coupler_right.stl" scale=" .001 .001 .001" />
			</geometry>
		</collision> -->
	</link>

	<xacro:pisa_hand parent="wrist_right" name="pisa_hand_right" left="false">
		<origin xyz="0.002 0.009 0.038" rpy="0 0 0"/>
	</xacro:pisa_hand>


</robot>